<?xml version="1.0"?>
<robot xmlns:xacro="http://www.ros.org/wiki/xacro">

    <xacro:macro name="wheel_joint" params="name parent_link child_link xyz">
        <joint name="${name}" type="continuous">
            <parent link="${parent_link}"/>
            <child link="${child_link}"/>
            <origin rpy="0 0 0" xyz="${xyz}"/>
            <axis xyz="0 1 0"/>
            <dynamics damping="1.0" friction="0.2" spring_stiffness="1"/>
            <limit effort="50" velocity="0.7"/>
        </joint>
        <transmission name="${name}_trans">
            <type>transmission_interface/SimpleTransmission</type>
            <joint name="${name}">
                <hardwareInterface>hardware_interface/VelocityJointInterface</hardwareInterface>
            </joint>
            <actuator name="${name}_wheel_motor">
                <hardwareInterface>hardware_interface/VelocityJointInterface</hardwareInterface>
                <mechanicalReduction>1</mechanicalReduction>
            </actuator>
        </transmission>
    </xacro:macro>

</robot>